Traceback (most recent call last):
  File "/usr/local/lib/python3.9/dist-packages/jupyter_cache/executors/utils.py", line 58, in single_nb_execution
    executenb(
  File "/usr/local/lib/python3.9/dist-packages/nbclient/client.py", line 1204, in execute
    return NotebookClient(nb=nb, resources=resources, km=km, **kwargs).execute()
  File "/usr/local/lib/python3.9/dist-packages/nbclient/util.py", line 84, in wrapped
    return just_run(coro(*args, **kwargs))
  File "/usr/local/lib/python3.9/dist-packages/nbclient/util.py", line 62, in just_run
    return loop.run_until_complete(coro)
  File "/usr/lib/python3.9/asyncio/base_events.py", line 647, in run_until_complete
    return future.result()
  File "/usr/local/lib/python3.9/dist-packages/nbclient/client.py", line 663, in async_execute
    await self.async_execute_cell(
  File "/usr/local/lib/python3.9/dist-packages/nbclient/client.py", line 965, in async_execute_cell
    await self._check_raise_for_error(cell, cell_index, exec_reply)
  File "/usr/local/lib/python3.9/dist-packages/nbclient/client.py", line 862, in _check_raise_for_error
    raise CellExecutionError.from_cell_and_msg(cell, exec_reply_content)
nbclient.exceptions.CellExecutionError: An error occurred while executing the following cell:
------------------
up.uses_netloc.append("postgres")
url = up.urlparse("postgres://vxvfdqsv:zE_56p9mPiltOOEuuu2Aj4EBEtyfuQpf@floppy.db.elephantsql.com/vxvfdqsv") # link URL database
conn = psycopg2.connect(database=url.path[1:], user=url.username, password=url.password, host=url.hostname, port=url.port)
------------------

[0;31m[0m
[0;31mOperationalError[0mTraceback (most recent call last)
[0;32m<ipython-input-3-3d747a82bf0f>[0m in [0;36m<module>[0;34m[0m
[1;32m      1[0m [0mup[0m[0;34m.[0m[0muses_netloc[0m[0;34m.[0m[0mappend[0m[0;34m([0m[0;34m"postgres"[0m[0;34m)[0m[0;34m[0m[0;34m[0m[0m
[1;32m      2[0m [0murl[0m [0;34m=[0m [0mup[0m[0;34m.[0m[0murlparse[0m[0;34m([0m[0;34m"postgres://vxvfdqsv:zE_56p9mPiltOOEuuu2Aj4EBEtyfuQpf@floppy.db.elephantsql.com/vxvfdqsv"[0m[0;34m)[0m [0;31m# link URL database[0m[0;34m[0m[0;34m[0m[0m
[0;32m----> 3[0;31m [0mconn[0m [0;34m=[0m [0mpsycopg2[0m[0;34m.[0m[0mconnect[0m[0;34m([0m[0mdatabase[0m[0;34m=[0m[0murl[0m[0;34m.[0m[0mpath[0m[0;34m[[0m[0;36m1[0m[0;34m:[0m[0;34m][0m[0;34m,[0m [0muser[0m[0;34m=[0m[0murl[0m[0;34m.[0m[0musername[0m[0;34m,[0m [0mpassword[0m[0;34m=[0m[0murl[0m[0;34m.[0m[0mpassword[0m[0;34m,[0m [0mhost[0m[0;34m=[0m[0murl[0m[0;34m.[0m[0mhostname[0m[0;34m,[0m [0mport[0m[0;34m=[0m[0murl[0m[0;34m.[0m[0mport[0m[0;34m)[0m[0;34m[0m[0;34m[0m[0m
[0m
[0;32m/usr/local/lib/python3.9/dist-packages/psycopg2/__init__.py[0m in [0;36mconnect[0;34m(dsn, connection_factory, cursor_factory, **kwargs)[0m
[1;32m    120[0m [0;34m[0m[0m
[1;32m    121[0m     [0mdsn[0m [0;34m=[0m [0m_ext[0m[0;34m.[0m[0mmake_dsn[0m[0;34m([0m[0mdsn[0m[0;34m,[0m [0;34m**[0m[0mkwargs[0m[0;34m)[0m[0;34m[0m[0;34m[0m[0m
[0;32m--> 122[0;31m     [0mconn[0m [0;34m=[0m [0m_connect[0m[0;34m([0m[0mdsn[0m[0;34m,[0m [0mconnection_factory[0m[0;34m=[0m[0mconnection_factory[0m[0;34m,[0m [0;34m**[0m[0mkwasync[0m[0;34m)[0m[0;34m[0m[0;34m[0m[0m
[0m[1;32m    123[0m     [0;32mif[0m [0mcursor_factory[0m [0;32mis[0m [0;32mnot[0m [0;32mNone[0m[0;34m:[0m[0;34m[0m[0;34m[0m[0m
[1;32m    124[0m         [0mconn[0m[0;34m.[0m[0mcursor_factory[0m [0;34m=[0m [0mcursor_factory[0m[0;34m[0m[0;34m[0m[0m

[0;31mOperationalError[0m: FATAL:  too many connections for role "vxvfdqsv"

OperationalError: FATAL:  too many connections for role "vxvfdqsv"


